<?xml version="1.0"?>
<robot xmlns:xacro="http://www.ros.org/wiki/xacro" name="krowka">

    <xacro:macro name="link_2" params="parent trans_x trans_y trans_z name low_limit high_limit effort velocity damping">

        <!-- LINK -->
        <xacro:macro name="link_2_mesh">
            <origin rpy="0 0 3.1416" xyz="0 0 0"/>
            <geometry>
                <mesh filename="package://krowka_model/urdf/krowka/mesh/stl/link_2.stl" scale="0.01 0.01 0.01"/>
            </geometry>
        </xacro:macro>

        <xacro:macro name="link_2_primitive">
            <origin rpy="0 0 0" xyz="0 0 0.137525"/>
            <geometry>
                <!-- <box size="0.015 0.015 0.2755"/> -->
                <cylinder radius="0.020" length="0.2755"/>
            </geometry>
        </xacro:macro>

        <xacro:macro name="link_2_color">
            <material name="link_2_color">
                <color rgba=".3 .2 .7 1"/>
            </material>
        </xacro:macro>

        <link name="${name}">
            <visual>
                <xacro:link_2_primitive/>
                <xacro:link_2_color/>
            </visual>

            <collision>
                <xacro:link_2_primitive/>
            </collision>

            <inertial>
                <origin rpy="0 0 3.1416" xyz="0 0 0" />
                <mass value="0.638"/>
                <inertia ixx="0.005" ixy="0.000" ixz="-0.001" iyy="0.005" iyz="0.000" izz="0.001"/>
            </inertial>
        </link>
        <gazebo reference="${name}">
            <mu1> .2 </mu1>
            <mu2> .2 </mu2>
            <material> Gazebo/Orange </material>
            <selfCollide>False</selfCollide>
        </gazebo>

        <!-- JOINT -->
        <joint name="${name}_joint" type="revolute">
            <parent link="${parent}"/>
            <child link="${name}"/>
            <origin rpy="0 0 0" xyz="${trans_x} ${trans_y} ${trans_z}"/>
            <axis xyz="0 1 0"/>
            <limit effort="${effort}" velocity="${velocity}" lower="${low_limit}" upper="${high_limit}"/>
            <dynamics damping="${damping}"/>
        </joint>
        <gazebo reference="${name}_joint">
            <stopCfm>0.8</stopCfm>
            <stopErp>0.5</stopErp>
            <provideFeedback>true</provideFeedback>
            <implicitSpringDamper>true</implicitSpringDamper>
            <fudgeFactor>0.0</fudgeFactor>
        </gazebo>

        <!-- TRANSMISSION -->
        <transmission name="${name}_transmission">
            <type>transmission_interface/SimpleTransmission</type>
            <joint name="${name}_joint">
                <hardwareInterface>EffortJointInterface</hardwareInterface>
            </joint>
            <actuator name="${name}_motor">
                <hardwareInterface>EffortJointInterface</hardwareInterface>
                <mechanicalReduction>1</mechanicalReduction>
            </actuator>
        </transmission>

    </xacro:macro>
</robot>
