<?xml version="1.0"?>
<robot xmlns:xacro="http://www.ros.org/wiki/xacro" name="krowka">

    <xacro:macro name="grip" params="parent trans_x trans_y trans_z name low_limit high_limit effort velocity damping rot_yaw axis no">

        <!-- LINK -->
        <xacro:macro name="grip_mesh">
            <origin rpy="0 ${rot_yaw} 0" xyz="0 0 0"/>
            <geometry>
                <mesh filename="package://krowka_model/urdf/krowka/mesh/stl/grip_${no}.stl" scale="0.01 0.01 0.01"/>
            </geometry>
        </xacro:macro>

        <xacro:macro name="grip_primitive">
            <origin rpy="0 0 0" xyz="0 0 0.025"/>
            <geometry>
                <box size="0.01 0.025 0.1"/>
            </geometry>
        </xacro:macro>

        <xacro:macro name="grip_color">
            <material name="grip_color">
                <color rgba=".3 .2 .7 1"/>
            </material>
        </xacro:macro>

        <link name="${name}">
            <visual>
                <xacro:grip_primitive/>
                <xacro:grip_color/>
            </visual>

            <collision>
                <xacro:grip_primitive/>
            </collision>

            <inertial>
                <origin rpy="0 0 0" xyz="0 0 0" />
                <mass value="0.017"/>
                <inertia ixx="0.000013" ixy="0.000" ixz="-0.000002" iyy="0.000013" iyz="0.000" izz="0.000002"/>
            </inertial>
        </link>
        <gazebo reference="${name}">
            <mu1> 1 </mu1>
            <mu2> 1 </mu2>
            <kp> 1160000 </kp>
            <kd> 1000 </kd>
            <material> Gazebo/White </material>
            <selfCollide>False</selfCollide>
        </gazebo>

        <!-- JOINT -->
        <joint name="${name}_joint" type="revolute">
            <parent link="${parent}"/>
            <child link="${name}"/>
            <origin rpy="0 0 0" xyz="${trans_x} ${trans_y} ${trans_z}"/>
            <axis xyz="0 ${axis} 0"/>
            <limit effort="${effort}" velocity="${velocity}" lower="${low_limit}" upper="${high_limit}"/>
            <dynamics damping="1" friction="5"/>
        </joint>
        <gazebo reference="${name}_joint">
            <!-- <stopCfm>0.8</stopCfm>
            <stopErp>0.5</stopErp> -->
            <provideFeedback>true</provideFeedback>
            <implicitSpringDamper>true</implicitSpringDamper>
            <fudgeFactor>0.0</fudgeFactor>
        </gazebo>

        <!-- TRANSMISSION -->
        <transmission name="${name}_transmission">
            <type>transmission_interface/SimpleTransmission</type>
            <joint name="${name}_joint">
                <hardwareInterface>EffortJointInterface</hardwareInterface>
            </joint>
            <actuator name="${name}_motor">
                <hardwareInterface>EffortJointInterface</hardwareInterface>
                <mechanicalReduction>1</mechanicalReduction>
            </actuator>
        </transmission>

    </xacro:macro>
</robot>
