<?xml version="1.0" ?>
<!-- =================================================================================== -->
<!-- |    This document was autogenerated by xacro from krowka.xacro                   | -->
<!-- |    EDITING THIS FILE BY HAND IS NOT RECOMMENDED                                 | -->
<!-- =================================================================================== -->
<robot name="krowka" xmlns:xacro="http://www.ros.org/wiki/xacro">
  <!-- FILES INCLUDED -->
  <gazebo>
    <plugin filename="libgazebo_ros_control.so" name="gazebo_ros_control">
      <robotNamespace>/krowka</robotNamespace>
    </plugin>
  </gazebo>
  <!-- MODEL DEFINITION -->
  <!-- WORLD -->
  <link name="world"/>
  <joint name="fixed" type="fixed">
    <parent link="world"/>
    <child link="base_link"/>
  </joint>
  <link name="base_link">
    <visual>
      <origin rpy="0 0 0" xyz="0 0 0.06"/>
      <geometry>
        <box size="1 1 .1"/>
      </geometry>
      <material name="base_link_color">
        <color rgba=".8 .8 .8 1"/>
      </material>
    </visual>
    <collision>
      <origin rpy="0 0 0" xyz="0 0 0.06"/>
      <geometry>
        <box size="1 1 .1"/>
      </geometry>
    </collision>
    <inertial>
      <origin rpy="0 0 0" xyz="0 0 0"/>
      <mass value="1.070"/>
      <inertia ixx="0.009" ixy="0.000" ixz="-0.002" iyy="0.010" iyz="0.000" izz="0.005"/>
    </inertial>
  </link>
  <gazebo reference="base_link">
    <mu1> .2 </mu1>
    <mu2> .2 </mu2>
    <material> Gazebo/Black </material>
    <selfCollide>False</selfCollide>
  </gazebo>
  <!-- <xacro:camera_link  parent="base_link"
                        trans_x=" 0.200"
                        trans_y="-0.300"
                        trans_z=" 0.500"
                        rot_roll="0.0"
                        rot_pitch="0.7"
                        rot_yaw="2.5"
                        name="camera1"
        /> -->
  <!-- Kinematic description of manipulator. Variables trans_x, trans_y, trans_z contains translations
         of featured link relarively to its parent link, in parent's coordinate frame.
         Origin's rotations are not required, becouse in initial pose rotations of all
         links are the same (arm is directed to thr top)
         Limits, effort, (max) velocity and damping are properties of joint
         between featured link and it's parent link-->
  <link name="link_0">
    <visual>
      <origin rpy="0 0 0" xyz="0 0 0.035"/>
      <geometry>
        <!-- <box size="0.04 0.04 0.070"/> -->
        <cylinder length="0.070" radius="0.050"/>
      </geometry>
      <material name="link_0_color">
        <color rgba=".3 .2 .7 1"/>
      </material>
    </visual>
    <collision>
      <origin rpy="0 0 0" xyz="0 0 0.035"/>
      <geometry>
        <!-- <box size="0.04 0.04 0.070"/> -->
        <cylinder length="0.070" radius="0.050"/>
      </geometry>
    </collision>
    <inertial>
      <origin rpy="0 0 0" xyz="0 0 0"/>
      <mass value="1.082"/>
      <inertia ixx="0.005" ixy="0.000" ixz="0.000" iyy="0.003" iyz="-0.001" izz="0.003"/>
    </inertial>
  </link>
  <gazebo reference="link_0">
    <mu1> .2 </mu1>
    <mu2> .2 </mu2>
    <material> Gazebo/Grey </material>
    <selfCollide>False</selfCollide>
  </gazebo>
  <!-- JOINT -->
  <joint name="link_0_joint" type="revolute">
    <parent link="base_link"/>
    <child link="link_0"/>
    <origin rpy="0 0 0" xyz="0.0 0.0 0.12"/>
    <axis xyz="0 0 1"/>
    <limit effort="10" lower="-3.14" upper="3.14" velocity="0.4"/>
    <dynamics damping="10"/>
  </joint>
  <gazebo reference="link_0_joint">
    <stopCfm>0.8</stopCfm>
    <stopErp>0.5</stopErp>
    <provideFeedback>true</provideFeedback>
    <implicitSpringDamper>true</implicitSpringDamper>
    <fudgeFactor>0.0</fudgeFactor>
  </gazebo>
  <!-- TRANSMISSION -->
  <transmission name="link_0_transmission">
    <type>transmission_interface/SimpleTransmission</type>
    <joint name="link_0_joint">
      <hardwareInterface>EffortJointInterface</hardwareInterface>
    </joint>
    <actuator name="link_0_motor">
      <hardwareInterface>EffortJointInterface</hardwareInterface>
      <mechanicalReduction>1</mechanicalReduction>
    </actuator>
  </transmission>
  <link name="link_1">
    <visual>
      <origin rpy="0 0 0" xyz="0 0 0.180"/>
      <geometry>
        <!-- <box size="0.02 0.02 0.360"/> -->
        <cylinder length="0.360" radius="0.030"/>
      </geometry>
      <material name="link_1_color">
        <color rgba=".3 .2 .7 1"/>
      </material>
    </visual>
    <collision>
      <origin rpy="0 0 0" xyz="0 0 0.180"/>
      <geometry>
        <!-- <box size="0.02 0.02 0.360"/> -->
        <cylinder length="0.360" radius="0.030"/>
      </geometry>
    </collision>
    <inertial>
      <origin rpy="0 0 0" xyz="0 0 0"/>
      <mass value="1.234"/>
      <inertia ixx="0.014" ixy="0.000" ixz="0.000" iyy="0.013" iyz="-0.002" izz=".002"/>
    </inertial>
  </link>
  <gazebo reference="link_1">
    <mu1> .2 </mu1>
    <mu2> .2 </mu2>
    <material> Gazebo/Grey </material>
    <selfCollide>False</selfCollide>
  </gazebo>
  <!-- JOINT -->
  <joint name="link_1_joint" type="revolute">
    <parent link="link_0"/>
    <child link="link_1"/>
    <origin rpy="0 0 0" xyz="-0.025 0.0 0.07"/>
    <axis xyz="0 1 0"/>
    <limit effort="10" lower="-1.9" upper="2.0" velocity="0.4"/>
    <dynamics damping="10"/>
  </joint>
  <gazebo reference="link_1_joint">
    <stopCfm>0.8</stopCfm>
    <stopErp>0.5</stopErp>
    <provideFeedback>true</provideFeedback>
    <implicitSpringDamper>true</implicitSpringDamper>
    <fudgeFactor>0.0</fudgeFactor>
  </gazebo>
  <!-- TRANSMISSION -->
  <transmission name="link_1_transmission">
    <type>transmission_interface/SimpleTransmission</type>
    <joint name="link_1_joint">
      <hardwareInterface>EffortJointInterface</hardwareInterface>
    </joint>
    <actuator name="link_1_motor">
      <hardwareInterface>EffortJointInterface</hardwareInterface>
      <mechanicalReduction>1</mechanicalReduction>
    </actuator>
  </transmission>
  <link name="link_2">
    <visual>
      <origin rpy="0 0 0" xyz="0 0 0.137525"/>
      <geometry>
        <!-- <box size="0.015 0.015 0.2755"/> -->
        <cylinder length="0.2755" radius="0.020"/>
      </geometry>
      <material name="link_2_color">
        <color rgba=".3 .2 .7 1"/>
      </material>
    </visual>
    <collision>
      <origin rpy="0 0 0" xyz="0 0 0.137525"/>
      <geometry>
        <!-- <box size="0.015 0.015 0.2755"/> -->
        <cylinder length="0.2755" radius="0.020"/>
      </geometry>
    </collision>
    <inertial>
      <origin rpy="0 0 3.1416" xyz="0 0 0"/>
      <mass value="0.638"/>
      <inertia ixx="0.005" ixy="0.000" ixz="-0.001" iyy="0.005" iyz="0.000" izz="0.001"/>
    </inertial>
  </link>
  <gazebo reference="link_2">
    <mu1> .2 </mu1>
    <mu2> .2 </mu2>
    <material> Gazebo/Grey </material>
    <selfCollide>False</selfCollide>
  </gazebo>
  <!-- JOINT -->
  <joint name="link_2_joint" type="revolute">
    <parent link="link_1"/>
    <child link="link_2"/>
    <origin rpy="0 0 0" xyz="0.0 0.0 0.36"/>
    <axis xyz="0 1 0"/>
    <limit effort="5" lower="-2.0" upper="2.8" velocity="0.4"/>
    <dynamics damping="5"/>
  </joint>
  <gazebo reference="link_2_joint">
    <stopCfm>0.8</stopCfm>
    <stopErp>0.5</stopErp>
    <provideFeedback>true</provideFeedback>
    <implicitSpringDamper>true</implicitSpringDamper>
    <fudgeFactor>0.0</fudgeFactor>
  </gazebo>
  <!-- TRANSMISSION -->
  <transmission name="link_2_transmission">
    <type>transmission_interface/SimpleTransmission</type>
    <joint name="link_2_joint">
      <hardwareInterface>EffortJointInterface</hardwareInterface>
    </joint>
    <actuator name="link_2_motor">
      <hardwareInterface>EffortJointInterface</hardwareInterface>
      <mechanicalReduction>1</mechanicalReduction>
    </actuator>
  </transmission>
  <link name="link_3">
    <visual>
      <origin rpy="0 0 0" xyz="0 0 0.053"/>
      <geometry>
        <!-- <box size="0.01 0.01 0.106"/> -->
        <cylinder length="0.106" radius="0.015"/>
      </geometry>
      <material name="link_3_color">
        <color rgba=".3 .2 .7 1"/>
      </material>
    </visual>
    <collision>
      <origin rpy="0 0 0" xyz="0 0 0.053"/>
      <geometry>
        <!-- <box size="0.01 0.01 0.106"/> -->
        <cylinder length="0.106" radius="0.015"/>
      </geometry>
    </collision>
    <inertial>
      <origin rpy="0 0 0" xyz="0 0 0"/>
      <mass value="0.046"/>
      <inertia ixx="0.000016" ixy="0.000000" ixz="0.000000" iyy="0.000016" iyz="0.000" izz="0.000009"/>
    </inertial>
  </link>
  <gazebo reference="link_3">
    <mu1> .2 </mu1>
    <mu2> .2 </mu2>
    <material> Gazebo/Grey </material>
    <selfCollide>False</selfCollide>
  </gazebo>
  <!-- JOINT -->
  <joint name="link_3_joint" type="revolute">
    <parent link="link_2"/>
    <child link="link_3"/>
    <origin rpy="0 0 0" xyz="0.0 0.0 0.2755"/>
    <axis xyz="0 1 0"/>
    <limit effort="5" lower="-2.1" upper="2.1" velocity="0.4"/>
    <dynamics damping="3"/>
  </joint>
  <gazebo reference="link_3_joint">
    <stopCfm>0.8</stopCfm>
    <stopErp>0.5</stopErp>
    <provideFeedback>true</provideFeedback>
    <implicitSpringDamper>true</implicitSpringDamper>
    <fudgeFactor>0.0</fudgeFactor>
  </gazebo>
  <!-- TRANSMISSION -->
  <transmission name="link_3_transmission">
    <type>transmission_interface/SimpleTransmission</type>
    <joint name="link_3_joint">
      <hardwareInterface>EffortJointInterface</hardwareInterface>
    </joint>
    <actuator name="link_3_motor">
      <hardwareInterface>EffortJointInterface</hardwareInterface>
      <mechanicalReduction>1</mechanicalReduction>
    </actuator>
  </transmission>
  <!-- <xacro:grip     parent="link_3"
                    trans_x="0.02"
                    trans_y="0.000"
                    trans_z="0.106"
                    name="grip_0"
                    low_limit="-0.2"
                    high_limit="0.5"
                    effort="10"
                    velocity="0.4"
                    damping="3"
                    axis="1"
                    rot_yaw="0.00"
                    no="0"/>

    <xacro:grip     parent="link_3"
                    trans_x="-0.02"
                    trans_y="0.000"
                    trans_z="0.106"
                    name="grip_1"
                    low_limit="-0.2"
                    high_limit="0.5"
                    effort="10"
                    velocity="0.4"
                    damping="3"
                    axis="-1"
                    rot_yaw="3.1416"
                    no="1"/> -->
</robot>

